replay_output/BTCUSDT_orderbook.csv
tsec,tnsec,seqNo,id,type,side,bid0,bid1,bid2,bid3,bid4,bid_size0,bid_size1,bid_size2,bid_size3,bid_size4,ask0,ask1,ask2,ask3,ask4,ask_size0,ask_size1,ask_size2,ask_size3,ask_size4
1780775211,864392000,0,1,U,N,6060399000000,6060398000000,6060397000000,6060392000000,0,339209000,35000,17000,400000,0,6060400000000,6060401000000,6060402000000,6060584000000,0,17741000,80000,17000,18000,0
1780775211,864622000,2,1,U,N,6060399000000,6060398000000,6060397000000,6060392000000,0,339209000,35000,17000,400000,0,6060400000000,6060401000000,6060402000000,6060584000000,0,17741000,80000,17000,18000,0
1780775211,864645000,5,1,U,N,6060399000000,6060398000000,6060397000000,6060392000000,0,339173000,35000,17000,400000,0,6060400000000,6060401000000,6060402000000,6060584000000,0,17741000,80000,17000,18000,0
1780775211,864662000,7,1,U,N,6060399000000,6060398000000,6060397000000,6060392000000,0,339173000,35000,17000,400000,0,6060400000000,6060401000000,6060402000000,6060584000000,0,17741000,80000,17000,18000,0
1780775211,864678000,9,1,U,N,6060399000000,6060398000000,6060397000000,6060392000000,0,339173000,35000,17000,400000,0,6060400000000,6060401000000,6060402000000,6060584000000,0,17741000,80000,17000,18000,0
1780775211,864695000,11,1,U,N,6060399000000,6060398000000,6060397000000,6060392000000,0,339173000,35000,17000,400000,0,6060400000000,6060401000000,6060402000000,6060584000000,0,17741000,80000,17000,18000,0
1780775211,864725000,13,1,U,N,6060399000000,6060398000000,6060397000000,6060392000000,0,339173000,35000,17000,400000,0,6060400000000,6060401000000,6060402000000,6060584000000,0,17741000,80000,17000,18000,0
1780775211,864742000,15,1,U,N,6060399000000,6060398000000,6060397000000,6060392000000,0,325365000,35000,17000,400000,0,6060400000000,6060401000000,6060402000000,6060584000000,0,17741000,80000,17000,18000,0
1780775211,864758000,17,1,U,N,6060399000000,6060398000000,6060397000000,6060392000000,0,325365000,35000,17000,400000,0,6060400000000,6060401000000,6060402000000,6060584000000,0,17741000,80000,17000,18000,0
1780775211,864775000,19,1,U,N,6060399000000,6060398000000,6060397000000,6060392000000,0,325369000,35000,17000,400000,0,6060400000000,6060401000000,6060402000000,6060584000000,0,17741000,80000,17000,18000,0
1780775211,864800000,21,1,U,N,6060399000000,6060398000000,6060397000000,6060392000000,0,325369000,35000,17000,400000,0,6060400000000,6060401000000,6060402000000,6060584000000,0,17750000,89000,17000,18000,0
1780775211,864819000,23,1,U,N,6060399000000,6060398000000,6060397000000,6060392000000,0,325369000,35000,17000,400000,0,6060400000000,6060401000000,6060402000000,6060584000000,0,17750000,89000,17000,18000,0
1780775211,864834000,25,1,U,N,6060399000000,6060398000000,6060397000000,6060392000000,0,325369000,35000,17000,400000,0,6060400000000,6060401000000,6060402000000,6060584000000,0,17750000,89000,17000,18000,0
1780775211,864853000,27,1,U,N,6060399000000,6060398000000,6060397000000,6060392000000,6060364000000,194903000,98000,17000,400000,18000,6060400000000,6060401000000,6060402000000,6060453000000,6060584000000,187964000,89000,17000,5863000,18000
1780775211,864939000,29,1,U,N,6060399000000,6060398000000,6060397000000,6060392000000,6060364000000,194729000,98000,17000,400000,18000,6060400000000,6060401000000,6060402000000,6060452000000,6060453000000,180474000,89000,17000,18000,5863000
1780775211,864967000,31,1,U,N,6060399000000,6060398000000,6060397000000,6060392000000,6060364000000,194729000,98000,17000,400000,18000,6060400000000,6060401000000,6060402000000,6060452000000,6060453000000,180540000,98000,17000,18000,5863000
1780775211,864986000,33,1,U,N,6060399000000,6060398000000,6060397000000,6060392000000,6060364000000,194720000,98000,17000,400000,18000,6060400000000,6060401000000,6060402000000,6060452000000,6060453000000,180474000,89000,17000,18000,5863000
1780775211,865014000,35,1,U,N,6060399000000,6060398000000,6060397000000,6060392000000,6060364000000,201143000,98000,17000,400000,18000,6060400000000,6060401000000,6060402000000,6060452000000,6060453000000,180474000,89000,17000,18000,5863000
1780775211,865032000,37,1,U,N,6060399000000,6060398000000,6060397000000,6060392000000,6060364000000,264843000,98000,17000,400000,18000,6060400000000,6060401000000,6060402000000,6060452000000,6060453000000,97442000,89000,17000,18000,5863000
1780775211,865051000,39,1,U,N,6060399000000,6060398000000,6060397000000,6060392000000,6060364000000,292012000,35000,17000,400000,18000,6060400000000,6060401000000,6060402000000,6060452000000,6060453000000,18574000,80000,17000,18000,5863000
1780775211,865114000,42,1,U,N,6060399000000,6060398000000,6060397000000,6060392000000,6060364000000,292829000,35000,17000,400000,18000,6060400000000,6060401000000,6060402000000,6060452000000,6060453000000,18658000,71000,17000,18000,5863000
1780775211,865151000,44,1,U,N,6060399000000,6060398000000,6060397000000,6060392000000,6060364000000,279021000,35000,17000,400000,18000,6060400000000,6060401000000,6060402000000,6060452000000,6060453000000,18408000,71000,17000,18000,5863000
1780775211,865169000,46,1,U,N,6060399000000,6060398000000,6060397000000,6060392000000,6060364000000,292829000,35000,17000,400000,18000,6060400000000,6060401000000,6060402000000,6060452000000,6060453000000,18408000,71000,17000,18000,5863000
1780775211,865187000,48,1,U,N,6060399000000,6060398000000,6060397000000,6060392000000,6060364000000,292829000,35000,17000,400000,18000,6060400000000,6060401000000,6060402000000,6060452000000,6060453000000,18408000,71000,17000,18000,5863000
1780775211,865217000,51,1,U,N,6060399000000,6060398000000,6060397000000,6060392000000,6060364000000,292829000,35000,17000,400000,18000,6060400000000,6060401000000,6060402000000,6060452000000,6060453000000,18392000,71000,17000,18000,5863000
1780775211,865236000,54,1,U,N,6060399000000,6060398000000,6060397000000,6060392000000,6060364000000,292813000,35000,17000,400000,18000,6060400000000,6060401000000,6060402000000,6060452000000,6060453000000,18392000,71000,17000,18000,5863000
1780775211,865254000,56,1,U,N,6060399000000,6060398000000,6060397000000,6060392000000,6060364000000,292813000,35000,17000,400000,18000,6060400000000,6060401000000,6060402000000,6060452000000,6060453000000,17692000,71000,17000,18000,5863000
1780775211,865271000,58,1,U,N,6060399000000,6060398000000,6060397000000,6060392000000,6060364000000,292813000,35000,17000,400000,18000,6060400000000,6060401000000,6060402000000,6060452000000,6060453000000,18392000,71000,17000,18000,5863000
1780775211,865301000,60,1,U,N,6060399000000,6060398000000,6060397000000,6060392000000,6060364000000,292813000,35000,17000,400000,18000,6060400000000,6060401000000,6060402000000,6060452000000,6060453000000,18392000,71000,17000,18000,5863000
1780775211,865317000,62,1,U,N,6060399000000,6060398000000,6060397000000,6060392000000,6060364000000,292813000,35000,17000,400000,18000,6060400000000,6060401000000,6060402000000,6060452000000,6060453000000,18392000,71000,17000,18000,5863000
1780775211,865333000,64,1,U,N,6060399000000,6060398000000,6060397000000,6060392000000,6060364000000,292813000,35000,17000,400000,18000,6060400000000,6060401000000,6060402000000,6060452000000,6060453000000,18392000,71000,17000,18000,5863000
1780775211,865349000,66,1,U,N,6060399000000,6060398000000,6060397000000,6060392000000,6060364000000,292813000,35000,17000,400000,18000,6060400000000,6060401000000,6060402000000,6060452000000,6060453000000,17692000,71000,17000,18000,5863000
1780775211,865368000,68,1,U,N,6060399000000,6060398000000,6060397000000,6060392000000,6060364000000,292813000,35000,17000,400000,18000,6060400000000,6060401000000,6060402000000,6060452000000,6060453000000,17692000,71000,17000,18000,5863000
1780775211,865391000,70,1,U,N,6060399000000,6060398000000,6060397000000,6060392000000,6060364000000,292813000,35000,17000,400000,18000,6060400000000,6060401000000,6060402000000,6060452000000,6060453000000,2402000,71000,17000,18000,5863000
1780775211,865412000,72,1,U,N,6060399000000,6060398000000,6060397000000,6060392000000,6060364000000,293802000,35000,17000,400000,18000,6060400000000,6060401000000,6060402000000,6060452000000,6060453000000,2375000,71000,17000,18000,5863000
