replay_output/market_data_binance_BTCUSDT.csv
recv_tsec,recv_tnsec,venue,stream_kind,shard_id,conn_epoch,conn_seq,symbol,payload_json
1780775211|864392000|binance|depth|0|0|0|BTCUSDT|"""{""lastUpdateId"":95210783222,""bids"":[[""60603.99000000"",""3.39209000""],[""60603.98000000"",""0.00035000""],[""60603.97000000"",""0.00017000""],[""60603.92000000"",""0.00400000""],[""60603.64000000"",""0.04091000""]],""asks"":[[""60604.00000000"",""0.17741000""],[""60604.01000000"",""0.00080000""],[""60604.02000000"",""0.00017000""],[""60605.84000000"",""0.00018000""],[""60605.85000000"",""0.03063000""]]}"""
1780775211|864616000|binance|depth|0|0|1|BTCUSDT|"""{""e"":""depthUpdate"",""E"":1780775025014,""s"":""BTCUSDT"",""U"":95210783213,""u"":95210783222,""b"":[[""60572.93000000"",""0.01249000""],[""60494.83000000"",""0.09918000""],[""54543.60000000"",""0.00500000""],[""48483.20000000"",""0.00087000""],[""48483.00000000"",""0.00200000""]],""a"":[[""60683.97000000"",""0.00898000""]]}"""
1780775211|864622000|binance|depth|0|0|2|BTCUSDT|"""{""lastUpdateId"":95210783231,""bids"":[[""60603.99000000"",""3.39209000""],[""60603.98000000"",""0.00035000""],[""60603.97000000"",""0.00017000""],[""60603.92000000"",""0.00400000""],[""60603.64000000"",""0.04091000""]],""asks"":[[""60604.00000000"",""0.17741000""],[""60604.01000000"",""0.00080000""],[""60604.02000000"",""0.00017000""],[""60605.84000000"",""0.00018000""],[""60605.85000000"",""0.03063000""]]}"""
1780775211|864637000|binance|depth|0|0|3|BTCUSDT|"""{""e"":""depthUpdate"",""E"":1780775025114,""s"":""BTCUSDT"",""U"":95210783223,""u"":95210783231,""b"":[[""54543.60000000"",""0.00500000""]],""a"":[[""60615.33000000"",""0.00048000""],[""60635.15000000"",""0.00000000""],[""60635.16000000"",""0.00200000""],[""60700.19000000"",""0.00898000""],[""60717.73000000"",""0.00070000""]]}"""
1780775211|864641000|binance|depth|0|0|4|BTCUSDT|"""{""e"":""trade"",""E"":1780775025205,""s"":""BTCUSDT"",""t"":6379750128,""p"":""60603.99000000"",""q"":""0.00036000"",""T"":1780775025205,""m"":true,""M"":true}"""
1780775211|864645000|binance|depth|0|0|5|BTCUSDT|"""{""lastUpdateId"":95210783240,""bids"":[[""60603.99000000"",""3.39173000""],[""60603.98000000"",""0.00035000""],[""60603.97000000"",""0.00017000""],[""60603.92000000"",""0.00400000""],[""60603.64000000"",""0.04091000""]],""asks"":[[""60604.00000000"",""0.17741000""],[""60604.01000000"",""0.00080000""],[""60604.02000000"",""0.00017000""],[""60605.84000000"",""0.00018000""],[""60605.85000000"",""0.03063000""]]}"""
1780775211|864657000|binance|depth|0|0|6|BTCUSDT|"""{""e"":""depthUpdate"",""E"":1780775025214,""s"":""BTCUSDT"",""U"":95210783232,""u"":95210783240,""b"":[[""60603.99000000"",""3.39173000""],[""54543.60000000"",""0.00500000""],[""48483.20000000"",""0.00046000""]],""a"":[[""60716.40000000"",""0.00898000""],[""60730.15000000"",""0.00000000""],[""60745.08000000"",""0.00143000""]]}"""
1780775211|864662000|binance|depth|0|0|7|BTCUSDT|"""{""lastUpdateId"":95210783249,""bids"":[[""60603.99000000"",""3.39173000""],[""60603.98000000"",""0.00035000""],[""60603.97000000"",""0.00017000""],[""60603.92000000"",""0.00400000""],[""60603.64000000"",""0.04091000""]],""asks"":[[""60604.00000000"",""0.17741000""],[""60604.01000000"",""0.00080000""],[""60604.02000000"",""0.00017000""],[""60605.84000000"",""0.00018000""],[""60605.85000000"",""0.03063000""]]}"""
1780775211|864674000|binance|depth|0|0|8|BTCUSDT|"""{""e"":""depthUpdate"",""E"":1780775025314,""s"":""BTCUSDT"",""U"":95210783241,""u"":95210783249,""b"":[[""54543.60000000"",""0.00500000""],[""54543.00000000"",""0.00000000""]],""a"":[[""60732.62000000"",""0.00897000""]]}"""
1780775211|864678000|binance|depth|0|0|9|BTCUSDT|"""{""lastUpdateId"":95210783262,""bids"":[[""60603.99000000"",""3.39173000""],[""60603.98000000"",""0.00035000""],[""60603.97000000"",""0.00017000""],[""60603.92000000"",""0.00400000""],[""60603.64000000"",""0.04091000""]],""asks"":[[""60604.00000000"",""0.17741000""],[""60604.01000000"",""0.00080000""],[""60604.02000000"",""0.00017000""],[""60605.84000000"",""0.00018000""],[""60605.85000000"",""0.03063000""]]}"""
1780775211|864690000|binance|depth|0|0|10|BTCUSDT|"""{""e"":""depthUpdate"",""E"":1780775025415,""s"":""BTCUSDT"",""U"":95210783250,""u"":95210783262,""b"":[[""60597.92000000"",""0.27700000""],[""54543.60000000"",""0.00500000""],[""54543.00000000"",""0.00000000""]],""a"":[[""60619.25000000"",""0.00400000""],[""60619.31000000"",""0.00000000""],[""60635.14000000"",""3.55673000""],[""60635.16000000"",""0.00000000""],[""60748.83000000"",""0.00897000""]]}"""
1780775211|864695000|binance|depth|0|0|11|BTCUSDT|"""{""lastUpdateId"":95210783275,""bids"":[[""60603.99000000"",""3.39173000""],[""60603.98000000"",""0.00035000""],[""60603.97000000"",""0.00017000""],[""60603.92000000"",""0.00400000""],[""60603.64000000"",""0.04091000""]],""asks"":[[""60604.00000000"",""0.17741000""],[""60604.01000000"",""0.00080000""],[""60604.02000000"",""0.00017000""],[""60605.84000000"",""0.00018000""],[""60605.85000000"",""0.03063000""]]}"""
1780775211|864720000|binance|depth|0|0|12|BTCUSDT|"""{""e"":""depthUpdate"",""E"":1780775025514,""s"":""BTCUSDT"",""U"":95210783263,""u"":95210783275,""b"":[[""60594.80000000"",""0.00800000""],[""60594.74000000"",""0.00000000""],[""54543.60000000"",""0.00500000""],[""54543.00000000"",""0.00000000""],[""48483.20000000"",""0.00087000""]],""a"":[[""60625.31000000"",""0.00400000""],[""60625.37000000"",""0.00000000""],[""60765.05000000"",""0.00897000""]]}"""
1780775211|864725000|binance|depth|0|0|13|BTCUSDT|"""{""lastUpdateId"":95210783289,""bids"":[[""60603.99000000"",""3.39173000""],[""60603.98000000"",""0.00035000""],[""60603.97000000"",""0.00017000""],[""60603.92000000"",""0.00400000""],[""60603.64000000"",""0.04091000""]],""asks"":[[""60604.00000000"",""0.17741000""],[""60604.01000000"",""0.00080000""],[""60604.02000000"",""0.00017000""],[""60605.84000000"",""0.00018000""],[""60605.85000000"",""0.03063000""]]}"""
1780775211|864737000|binance|depth|0|0|14|BTCUSDT|"""{""e"":""depthUpdate"",""E"":1780775025614,""s"":""BTCUSDT"",""U"":95210783276,""u"":95210783289,""b"":[[""60585.79000000"",""0.00009000""],[""60494.83000000"",""0.00000000""],[""54543.60000000"",""0.00500000""],[""54543.00000000"",""0.00000000""],[""48483.20000000"",""0.00046000""],[""33000.00000000"",""31.14030000""]],""a"":[[""60622.17000000"",""0.00009000""],[""60811.79000000"",""0.00000000""]]}"""
1780775211|864742000|binance|depth|0|0|15|BTCUSDT|"""{""lastUpdateId"":95210783296,""bids"":[[""60603.99000000"",""3.25365000""],[""60603.98000000"",""0.00035000""],[""60603.97000000"",""0.00017000""],[""60603.92000000"",""0.00400000""],[""60603.64000000"",""0.04091000""]],""asks"":[[""60604.00000000"",""0.17741000""],[""60604.01000000"",""0.00080000""],[""60604.02000000"",""0.00017000""],[""60605.84000000"",""0.00018000""],[""60605.85000000"",""0.03063000""]]}"""
1780775211|864754000|binance|depth|0|0|16|BTCUSDT|"""{""e"":""depthUpdate"",""E"":1780775025715,""s"":""BTCUSDT"",""U"":95210783290,""u"":95210783296,""b"":[[""60603.99000000"",""3.25365000""],[""60579.74000000"",""0.00490000""],[""60567.62000000"",""0.00618000""],[""54543.60000000"",""0.00500000""]],""a"":[]}"""
1780775211|864758000|binance|depth|0|0|17|BTCUSDT|"""{""lastUpdateId"":95210783313,""bids"":[[""60603.99000000"",""3.25365000""],[""60603.98000000"",""0.00035000""],[""60603.97000000"",""0.00017000""],[""60603.92000000"",""0.00400000""],[""60603.64000000"",""0.04091000""]],""asks"":[[""60604.00000000"",""0.17741000""],[""60604.01000000"",""0.00080000""],[""60604.02000000"",""0.00017000""],[""60605.84000000"",""0.00018000""],[""60605.85000000"",""0.03063000""]]}"""
1780775211|864770000|binance|depth|0|0|18|BTCUSDT|"""{""e"":""depthUpdate"",""E"":1780775025814,""s"":""BTCUSDT"",""U"":95210783297,""u"":95210783313,""b"":[[""60588.73000000"",""0.00400000""],[""60588.68000000"",""0.00000000""],[""54543.60000000"",""0.00480000""],[""54543.00000000"",""0.00000000""],[""48483.19000000"",""0.00000000""]],""a"":[[""60631.31000000"",""0.00400000""],[""60631.43000000"",""0.00000000""],[""60634.82000000"",""0.00200000""],[""60635.17000000"",""0.00000000""]]}"""
